<?xml version="1.0" ?>
<sdf xmlns:xacro="http://www.ros.org/wiki/xacro" version="1.10">
<model name="garage">
<pose>0 0 0 0 0 0</pose>
<static>false</static>

<xacro:include filename="$(env MODELS_DIR)/common/utils.xacro" />

<link name="garage">
    <self_collide>false</self_collide>
    <xacro:macro name="garage_stl">
        <geometry>
            <mesh>
                <uri>file:/$(env MODELS_DIR)/objects/garage/base1-asm.stl</uri>
                <scale>1 1 1</scale>
            </mesh>
        </geometry>
    </xacro:macro>
    <collision name="garage_collision">
        <xacro:garage_stl/>
    </collision>
    <visual name="garage_visual">
        <xacro:garage_stl/>
        <material>
            <script>
                <uri>file://media/materials/scripts/gazebo.material</uri>
                <name>Gazebo/White</name>
            </script>
        </material>
    </visual>
    <xacro:cuboid_inertia pose="2 1 1 0 0 0" weight="10000" a="4" b="2" c="2"/>
</link>

<link name="door">
    <self_collide>false</self_collide>
    <pose>0.4 0.05 0.1 0 0 0</pose>
    <xacro:macro name="door_stl">
        <geometry>
            <mesh>
            <uri>file:/$(env MODELS_DIR)/objects/garage/base-door.stl</uri>
            <scale>1 1 1</scale>
            </mesh>
        </geometry>
    </xacro:macro>
    <collision name="garage_collision">
        <xacro:door_stl/>
    </collision>
    <visual name="garage_visual">
        <xacro:door_stl/>
        <material>
            <script>
                <uri>file://media/materials/scripts/gazebo.material</uri>
                <name>Gazebo/Blue</name>
            </script>
        </material>
    </visual>
    <xacro:cuboid_inertia weight="5" a="0.2" b="0.7" c="2"/>
</link>

<joint name="garage_door_joint" type="prismatic">
    <parent>garage</parent>
    <child>door</child>
    <axis>
        <xyz>1 0 0</xyz>
        <limit>
            <lower>0</lower>
            <upper>1</upper>
        </limit>
        <dynamics>
            <damping>0</damping>
            <spring_stiffness>0</spring_stiffness>
            <spring_reference>0</spring_reference>
        </dynamics>
    </axis>
    <physics>
        <ode>
            <cfm_damping>1</cfm_damping>
        </ode>
    </physics>
</joint>

<xacro:include filename="$(env MODELS_DIR)/objects/button/button.xacro" />
<xacro:macro name="garage_button" params="name pose">
    <model name="${name}_button">
        <pose>${pose}</pose>
        <xacro:button name_prefix="${name}_"/>
    </model>
    <joint name="${name}_button_to_wall_joint" type="fixed">
        <parent>garage</parent>
        <child>${name}_button::${name}_frame</child>
    </joint>
</xacro:macro>

<xacro:garage_button name="outer_open" pose="1.65 0 0.85 ${-pi/2} 0 ${pi}"/>
<xacro:garage_button name="outer_close" pose="1.65 0 0.7 ${-pi/2} 0 ${pi}"/>
<xacro:garage_button name="inner_open" pose="0.1 0.4 0.9 0 ${-pi/2} ${pi}"/>
<xacro:garage_button name="inner_close" pose="0.1 0.4 0.7 0 ${-pi/2} ${pi}"/>

</model>
</sdf>
