<include xmlns:xacro="http://www.ros.org/wiki/xacro">
<xacro:macro name="wheel" params="index xyz yaw axis radius">

<link name="wheel_${index}_disc">
    <inertial>
        <mass value="1"/>
        <inertia ixx="0.043333" ixy="0" ixz="0" iyy="0.043333" iyz="0" izz="0.08"/>
    </inertial>
    <visual name="wheel_${index}_disc_visual">
        <geometry>
            <mesh filename="file://$(env MODELS_DIR)/rover/stl/wdisc.stl"/>
        </geometry>
        <material name="white-ish">
            <color rgba="0.7 0.7 0.7 1.0"/>
        </material>
    </visual>
    <collision name='wheel_${index}_collision'>
        <geometry>
            <cylinder radius="${radius}" length="0.1"/>
        </geometry>
    </collision>
</link>

<link name="wheel_${index}_tyre">
    <visual name="wheel_${index}_tyre_visual">
        <geometry>
            <mesh filename="file://$(env MODELS_DIR)/rover/stl/tyre.stl"/>
        </geometry>
        <material name="black">
            <color rgba="0 0 0 1.0"/>
        </material>
    </visual>
</link>

<joint name="wheel_${index}_tyre_to_disc_joint" type="fixed">
    <parent link="wheel_${index}_disc"/>
    <child link="wheel_${index}_tyre"/>
</joint>

<joint name="wheel_${index}_joint" type="revolute">
    <parent link="base"/>
    <child link="wheel_${index}_disc"/>
    <origin xyz="${xyz}" rpy="${pi/2} 0 ${yaw}"/>
    <axis xyz="${axis}"/>
    <limit
        lower="-1.79769e+308"
        upper="+1.79769e+308"
        effort="100"
        velocity="100"
    />
</joint>

</xacro:macro>
</include>
